Workbook
Name Slicer_Region: #N/A
Name Slicer_Segment: #N/A
Name Slicer_Sub_Category: #N/A
Name Slicer_Ship_Mode: #N/A
Name Slicer_Category: #N/A
Name Slicer_City: #N/A
Name Slicer_State: #N/A

Sheet Ship mode
A3: Ship Mode | B3: Sum of Sales | C3: Sum of Discount | D3: Average of Sales
A4: Standard Class | B4: 205.3328 | C4: 0.32 | D4: 205.3328
A5: Grand Total | B5: 205.3328 | C5: 0.32 | D5: 205.3328

Sheet segment
A3: Category | B3: Count of Segment
A4: Furniture | B4: 26
A5: Office Supplies | B5: 48
A6: Technology | B6: 13
A7: Grand Total | B7: 87

Sheet category
A1: Category | B1: Furniture
A3: Ship Mode | B3: Sum of Sales | C3: Sum of Profit | D3: Sum of Adujested sales
A4: First Class | B4: 3113.569 | C4: 777.3104 | D4: 2445.9267
A5: Grand Total | B5: 3113.569 | C5: 777.3104 | D5: 2445.9267

Sheet SALES
A1: Category | B1: (ALL)
A2: Sub-Category | B2: Art
A4: Product Name | B4: Product ID | C4: Sum of Adujested sales | D4: Sum of Quantity | E4: Sum of Sales | F4: Sum of Profit | G4: Sum of Discount
A5: American Pencil | C5: 9.32 | D5: 4 | E5: 9.32 | F5: 2.7028 | G5: 0
B6: OFF-AR-10001573 | C6: 9.32 | D6: 4 | E6: 9.32 | F6: 2.7028 | G6: 0
A7: Avery Hi-Liter EverBold Pen Style Fluorescent Highlighters, 4/Pack | C7: 31.2576 | D7: 6 | E7: 39.072 | F7: 9.768 | G7: 0.2
B8: OFF-AR-10003478 | C8: 31.2576 | D8: 6 | E8: 39.072 | F8: 9.768 | G8: 0.2
A9: BIC Brite Liner Grip Highlighters, Assorted, 5/Pack | C9: 2.7136 | D9: 1 | E9: 3.392 | F9: 0.8056 | G9: 0.2
B10: OFF-AR-10000034 | C10: 2.7136 | D10: 1 | E10: 3.392 | F10: 0.8056 | G10: 0.2
A11: BIC Brite Liner Highlighters | C11: 16.2288 | D11: 5 | E11: 18.216 | F11: 6.21 | G11: 0.2
B12: OFF-AR-10004441 | C12: 16.2288 | D12: 5 | E12: 18.216 | F12: 6.21 | G12: 0.2
A13: Binney & Smith Crayola Metallic Colored Pencils, 8-Color Set | C13: 5.9264 | D13: 2 | E13: 7.408 | F13: 1.2038 | G13: 0.2
B14: OFF-AR-10004685 | C14: 5.9264 | D14: 2 | E14: 7.408 | F14: 1.2038 | G14: 0.2
A15: Binney & Smith Crayola Metallic Crayons, 16-Color Pack | C15: 13.48 | D15: 4 | E15: 13.48 | F15: 5.9312 | G15: 0
B16: OFF-AR-10001118 | C16: 13.48 | D16: 4 | E16: 13.48 | F16: 5.9312 | G16: 0
A17: Binney & Smith inkTank Erasable Desk Highlighter, Chisel Tip, Yellow, 12/Box | C17: 7.56 | D17: 3 | E17: 7.56 | F17: 3.0996 | G17: 0
B18: OFF-AR-10004027 | C18: 7.56 | D18: 3 | E18: 7.56 | F18: 3.0996 | G18: 0
A19: Boston 16801 Nautilus Battery Pencil Sharpener | C19: 72.1928 | D19: 4 | E19: 79.236 | F19: 14.0864 | G19: 0.2
B20: OFF-AR-10002956 | C20: 72.1928 | D20: 4 | E20: 79.236 | F20: 14.0864 | G20: 0.2
A21: Boston 19500 Mighty Mite Electric Pencil Sharpener | C21: 60.45 | D21: 3 | E21: 60.45 | F21: 16.3215 | G21: 0
B22: OFF-AR-10004648 | C22: 60.45 | D22: 3 | E22: 60.45 | F22: 16.3215 | G22: 0
A23: Boston School Pro Electric Pencil Sharpener, 1670 | C23: 423.8064 | D23: 18 | E23: 483.288 | F23: 76.2108 | G23: 0.4
B24: OFF-AR-10003373 | C24: 423.8064 | D24: 18 | E24: 483.288 | F24: 76.2108 | G24: 0.4
A25: Bulldog Vacuum Base Pencil Sharpener | C25: 95.92 | D25: 8 | E25: 95.92 | F25: 25.8984 | G25: 0
B26: OFF-AR-10004344 | C26: 95.92 | D26: 8 | E26: 95.92 | F26: 25.8984 | G26: 0
A27: Crayola Colored Pencils | C27: 2.0992 | D27: 1 | E27: 2.624 | F27: 0.4264 | G27: 0.2
B28: OFF-AR-10004757 | C28: 2.0992 | D28: 1 | E28: 2.624 | F28: 0.4264 | G28: 0.2
A29: Design Ebony Sketching Pencil | C29: 5.3376 | D29: 6 | E29: 6.672 | F29: 0.5004 | G29: 0.2
B30: OFF-AR-10000369 | C30: 5.3376 | D30: 6 | E30: 6.672 | F30: 0.5004 | G30: 0.2
A31: Dixon My First Ticonderoga Pencil, #2 | C31: 26.208 | D31: 7 | E31: 32.76 | F31: 3.6855 | G31: 0.2
B32: OFF-AR-10003405 | C32: 26.208 | D32: 7 | E32: 32.76 | F32: 3.6855 | G32: 0.2
A33: DIXON Oriole Pencils | C33: 5.16 | D33: 2 | E33: 5.16 | F33: 1.3416 | G33: 0
B34: OFF-AR-10002335 | C34: 5.16 | D34: 2 | E34: 5.16 | F34: 1.3416 | G34: 0
A35: Dixon Ticonderoga Core-Lock Colored Pencils | C35: 11.6608 | D35: 2 | E35: 14.576 | F35: 2.3686 | G35: 0.2
B36: OFF-AR-10003179 | C36: 11.6608 | D36: 2 | E36: 14.576 | F36: 2.3686 | G36: 0.2
A37: Faber Castell Col-Erase Pencils | C37: 4.89 | D37: 1 | E37: 4.89 | F37: 2.0049 | G37: 0
B38: OFF-AR-10002804 | C38: 4.89 | D38: 1 | E38: 4.89 | F38: 2.0049 | G38: 0
A39: Hunt BOSTON Model 1606 High-Volume Electric Pencil Sharpener, Beige | C39: 890.4192 | D39: 8 | E39: 1113.024 | F39: 111.3024 | G39: 0.2
B40: OFF-AR-10002671 | C40: 890.4192 | D40: 8 | E40: 1113.024 | F40: 111.3024 | G40: 0.2
A41: Hunt PowerHouse Electric Pencil Sharpener, Blue | C41: 75.96 | D41: 2 | E41: 75.96 | F41: 22.788 | G41: 0
...

Sheet Customer
A1: Segment | B1: Consumer
A2: Country | B2: (ALL)
A3: Region | B3: (ALL)
A5: Customer ID | B5: Customer Name | C5: City | D5: State | E5: Postal Code | F5: Sum of Sales
A6: AA-10375 | F6: 45.168
B7: Allen Armold | F7: 45.168
C8: Mesa | F8: 16.768
D9: Arizona | F9: 16.768
E10: 85204 | F10: 16.768
C11: Omaha | F11: 28.4
D12: Nebraska | F12: 28.4
E13: 68104 | F13: 28.4
A14: AA-10480 | F14: 15.552
B15: Andrew Allen | F15: 15.552
C16: Concord | F16: 15.552
D17: North Carolina | F17: 15.552
E18: 28027 | F18: 15.552
A19: AB-10105 | F19: 23.64
B20: Adrian Barton | F20: 23.64
C21: Houston | F21: 23.64
D22: Texas | F22: 23.64
E23: 77041 | F23: 23.64
A24: AB-10165 | F24: 180.832
B25: Alan Barnes | F25: 180.832
C26: Los Angeles | F26: 166.24
D27: California | F27: 166.24
E28: 90036 | F28: 166.24
C29: Toledo | F29: 14.592
D30: Ohio | F30: 14.592
E31: 43615 | F31: 14.592
A32: AF-10885 | F32: 83.72
B33: Art Foster | F33: 83.72
C34: Louisville | F34: 83.72
D35: Kentucky | F35: 83.72
E36: 40214 | F36: 83.72
A37: AG-10270 | F37: 55.5
B38: Alejandro Grove | F38: 55.5
C39: West Jordan | F39: 55.5
D40: Utah | F40: 55.5
E41: 84084 | F41: 55.5
...

Sheet Superstores sales dataset
A1: Row ID | B1: Order ID | C1: Order Date | D1: Ship Date | E1: Ship Mode | F1: Customer ID | G1: Customer Name | H1: Segment | I1: Country | J1: City | K1: State | L1: Postal Code | M1: Region | N1: Product ID | O1: Category | P1: Sub-Category | Q1: Product Name | R1: Sales | S1: Quantity | T1: Discount | U1: Profit | V1: Profit | W1: Adujested sales | X1: Error flag
A2: 1 | B2: CA-2016-152156 | C2: 42682 | D2: 42685 | E2: Second Class | F2: CG-12520 | G2: Claire Gute | H2: Consumer | I2: United States | J2: Henderson | K2: Kentucky | L2: 42420 | M2: South | N2: FUR-BO-10001798 | O2: Furniture | P2: Bookcases | Q2: Bush Somerset Collection Bookcase | R2: 261.96 | S2: -671086.64 | T2: 0 | U2: 41.9136 | V2: {=ABS(U2:U539)} -> 41.9136 | W2: {=R2:R539*(1-T2:T539)} -> 261.96 | X2: {=IF(OR(R2:R539<0,T1:T539<0,C2:C540=""),"Check","OK")} -> OK
A3: 3 | B3: CA-2016-138688 | C3: 42533 | D3: 42537 | E3: Second Class | F3: DV-13045 | G3: Darrin Van Huff | H3: Corporate | I3: United States | J3: Los Angeles | K3: California | L3: 90036 | M3: West | N3: OFF-LA-10000240 | O3: Office Supplies | P3: Labels | Q3: Self-Adhesive Address Labels for Typewriters by Universal | R3: 14.62 | S3: 2 | T3: 0 | U3: 6.8714 | V3: 6.8714 | W3: 14.62 | X3: {=IF(OR(R3:R540<0,T2:T540<0,C3:C541=""),"Check","OK")} -> Check
A4: 4 | B4: US-2015-108966 | C4: 42288 | D4: 42295 | E4: Standard Class | F4: SO-20335 | G4: Sean O'Donnell | H4: Consumer | I4: United States | J4: Fort Lauderdale | K4: Florida | L4: 33311 | M4: South | N4: FUR-TA-10000577 | O4: Furniture | P4: Tables | Q4: Bretford CR4500 Series Slim Rectangular Table | R4: 957.5775 | S4: 5 | T4: 0.45 | U4: -383.031 | V4: 383.031 | W4: 526.66763 | X4: {=IF(OR(R4:R541<0,T3:T541<0,C4:C542=""),"Check","OK")} -> Check
A5: 6 | B5: CA-2014-115812 | C5: 41799 | D5: 41804 | E5: Standard Class | F5: BH-11710 | G5: Brosina Hoffman | H5: Consumer | I5: United States | J5: Los Angeles | K5: California | L5: 90032 | M5: West | N5: FUR-FU-10001487 | O5: Furniture | P5: Furnishings | Q5: Eldon Expressions Wood and Plastic Desk Accessories, Cherry Wood | R5: 48.86 | S5: 7 | T5: 0 | U5: 14.1694 | V5: 14.1694 | W5: 48.86 | X5: {=IF(OR(R5:R542<0,T4:T542<0,C5:C543=""),"Check","OK")} -> Check
A6: 13 | B6: CA-2017-114412 | C6: 42840 | D6: 42845 | E6: Standard Class | F6: AA-10480 | G6: Andrew Allen | H6: Consumer | I6: United States | J6: Concord | K6: North Carolina | L6: 28027 | M6: South | N6: OFF-PA-10002365 | O6: Office Supplies | P6: Paper | Q6: Xerox 1967 | R6: 15.552 | S6: 3 | T6: 0.2 | U6: 5.4432 | V6: 5.4432 | W6: 12.4416 | X6: {=IF(OR(R6:R543<0,T5:T543<0,C6:C544=""),"Check","OK")} -> Check | AA6: What if
A7: 14 | B7: CA-2016-161389 | C7: 42709 | D7: 42714 | E7: Standard Class | F7: IM-15070 | G7: Irene Maddox | H7: Consumer | I7: United States | J7: Seattle | K7: Washington | L7: 98103 | M7: West | N7: OFF-BI-10003656 | O7: Office Supplies | P7: Binders | Q7: Fellowes PB200 Plastic Comb Binding Machine | R7: 407.976 | S7: 3 | T7: 0.2 | U7: 132.5922 | V7: 132.5922 | W7: 326.3808 | X7: {=IF(OR(R7:R544<0,T6:T544<0,C7:C545=""),"Check","OK")} -> Check
A8: 15 | B8: US-2015-118983 | C8: 42330 | D8: 42334 | E8: Standard Class | F8: HP-14815 | G8: Harold Pawlan | H8: Home Office | I8: United States | J8: Fort Worth | K8: Texas | L8: 76106 | M8: Central | N8: OFF-AP-10002311 | O8: Office Supplies | P8: Appliances | Q8: Holmes Replacement Filter for HEPA Air Cleaner, Very Large Room, HEPA Filter | R8: 68.81 | S8: 5 | T8: 0.8 | U8: -123.858 | V8: 123.858 | W8: 13.762 | X8: {=IF(OR(R8:R545<0,T7:T545<0,C8:C546=""),"Check","OK")} -> Check
A9: 17 | B9: CA-2014-105893 | C9: 41954 | D9: 41961 | E9: Standard Class | F9: PK-19075 | G9: Pete Kriz | H9: Consumer | I9: United States | J9: Madison | K9: Wisconsin | L9: 53711 | M9: Central | N9: OFF-ST-10004186 | O9: Office Supplies | P9: Storage | Q9: Stur-D-Stor Shelving, Vertical 5-Shelf: 72"H x 36"W x 18 1/2"D | R9: 665.88 | S9: 6 | T9: 0 | U9: 13.3176 | V9: 13.3176 | W9: 665.88 | X9: {=IF(OR(R9:R546<0,T8:T546<0,C9:C547=""),"Check","OK")} -> Check
A10: 18 | B10: CA-2014-167164 | C10: 41772 | D10: 41774 | E10: Second Class | F10: AG-10270 | G10: Alejandro Grove | H10: Consumer | I10: United States | J10: West Jordan | K10: Utah | L10: 84084 | M10: West | N10: OFF-ST-10000107 | O10: Office Supplies | P10: Storage | Q10: Fellowes Super Stor/Drawer | R10: 55.5 | S10: 2 | T10: 0 | U10: 9.99 | V10: 9.99 | W10: 55.5 | X10: {=IF(OR(R10:R547<0,T9:T547<0,C10:C548=""),"Check","OK")} -> Check
A11: 19 | B11: CA-2014-143336 | C11: 41878 | D11: 41883 | E11: Second Class | F11: ZD-21925 | G11: Zuschuss Donatelli | H11: Consumer | I11: United States | J11: San Francisco | K11: California | L11: 94109 | M11: West | N11: OFF-AR-10003056 | O11: Office Supplies | P11: Art | Q11: Newell 341 | R11: 8.56 | S11: 2 | T11: 0 | U11: 2.4824 | V11: 2.4824 | W11: 8.56 | X11: {=IF(OR(R11:R548<0,T10:T548<0,C11:C549=""),"Check","OK")} -> Check
A12: 22 | B12: CA-2016-137330 | C12: 42713 | D12: 42717 | E12: Standard Class | F12: KB-16585 | G12: Ken Black | H12: Corporate | I12: United States | J12: Fremont | K12: Nebraska | L12: 68025 | M12: Central | N12: OFF-AR-10000246 | O12: Office Supplies | P12: Art | Q12: Newell 318 | R12: 19.46 | S12: 7 | T12: 0 | U12: 5.0596 | V12: 5.0596 | W12: 19.46 | X12: {=IF(OR(R12:R549<0,T11:T549<0,C12:C550=""),"Check","OK")} -> Check
A13: 24 | B13: US-2017-156909 | C13: 42932 | D13: 42934 | E13: Second Class | F13: SF-20065 | G13: Sandra Flanagan | H13: Consumer | I13: United States | J13: Philadelphia | K13: Pennsylvania | L13: 19140 | M13: East | N13: FUR-CH-10002774 | O13: Furniture | P13: Chairs | Q13: Global Deluxe Stacking Chair, Gray | R13: 71.372 | S13: 2 | T13: 0.3 | U13: -1.0196 | V13: 1.0196 | W13: 49.9604 | X13: {=IF(OR(R13:R550<0,T12:T550<0,C13:C551=""),"Check","OK")} -> Check
A14: 25 | B14: CA-2015-106320 | C14: 42272 | D14: 42277 | E14: Standard Class | F14: EB-13870 | G14: Emily Burns | H14: Consumer | I14: United States | J14: Orem | K14: Utah | L14: 84057 | M14: West | N14: FUR-TA-10000577 | O14: Furniture | P14: Tables | Q14: Bretford CR4500 Series Slim Rectangular Table | R14: 1044.63 | S14: 3 | T14: 0 | U14: 240.2649 | V14: 240.2649 | W14: 1044.63 | X14: {=IF(OR(R14:R551<0,T13:T551<0,C14:C552=""),"Check","OK")} -> Check
A15: 26 | B15: CA-2016-121755 | C15: 42385 | D15: 42389 | E15: Second Class | F15: EH-13945 | G15: Eric Hoffmann | H15: Consumer | I15: United States | J15: Los Angeles | K15: California | L15: 90049 | M15: West | N15: OFF-BI-10001634 | O15: Office Supplies | P15: Binders | Q15: Wilson Jones Active Use Binders | R15: 11.648 | S15: 2 | T15: 0.2 | U15: 4.2224 | V15: 4.2224 | W15: 9.3184 | X15: {=IF(OR(R15:R552<0,T14:T552<0,C15:C553=""),"Check","OK")} -> Check
A16: 28 | B16: US-2015-150630 | C16: 42264 | D16: 42268 | E16: Standard Class | F16: TB-21520 | G16: Tracy Blumstein | H16: Consumer | I16: United States | J16: Philadelphia | K16: Pennsylvania | L16: 19140 | M16: East | N16: FUR-BO-10004834 | O16: Furniture | P16: Bookcases | Q16: Riverside Palais Royal Lawyers Bookcase, Royale Cherry Finish | R16: 3083.43 | S16: 7 | T16: 0.5 | U16: -1665.0522 | V16: 1665.0522 | W16: 1541.715 | X16: {=IF(OR(R16:R553<0,T15:T553<0,C16:C554=""),"Check","OK")} -> Check
A17: 35 | B17: CA-2017-107727 | C17: 43027 | D17: 43031 | E17: Second Class | F17: MA-17560 | G17: Matt Abelman | H17: Home Office | I17: United States | J17: Houston | K17: Texas | L17: 77095 | M17: Central | N17: OFF-PA-10000249 | O17: Office Supplies | P17: Paper | Q17: Easy-staple paper | R17: 29.472 | S17: 3 | T17: 0.2 | U17: 9.9468 | V17: 9.9468 | W17: 23.5776 | X17: {=IF(OR(R17:R554<0,T16:T554<0,C17:C555=""),"Check","OK")} -> Check
A18: 36 | B18: CA-2016-117590 | C18: 42712 | D18: 42714 | E18: First Class | F18: GH-14485 | G18: Gene Hale | H18: Corporate | I18: United States | J18: Richardson | K18: Texas | L18: 75080 | M18: Central | N18: TEC-PH-10004977 | O18: Technology | P18: Phones | Q18: GE 30524EE4 | R18: 1097.544 | S18: 7 | T18: 0.2 | U18: 123.4737 | V18: 123.4737 | W18: 878.0352 | X18: {=IF(OR(R18:R555<0,T17:T555<0,C18:C556=""),"Check","OK")} -> Check
... A29: 63 | B29: CA-2015-135545 | C29: 42332 | D29: 42338 | E29: Standard Class | F29: KM-16720 | G29: Kunst Miller | H29: Consumer | I29: United States | J29: Los Angeles | K29: California | L29: 90004 | M29: West | N29: TEC-AC-10004633 | O29: Technology | P29: Accessories | Q29: Verbatim 25 GB 6x Blu-ray Single Layer Recordable Disc, 3/Pack | R29: 13.98 | S29: 2 | T29: 0 | U29: 6.1512 | V29: 6.1512 | W29: 13.98 | X29: {=IF(OR(R29:R566<0,T28:T566<0,C29:C567=""),"Check","OK")} -> OK
A30: 67 | B30: US-2015-164175 | C30: 42124 | D30: 42129 | E30: Standard Class | F30: PS-18970 | G30: Paul Stevenson | H30: Home Office | I30: United States | J30: Chicago | K30: Illinois | L30: 60610 | M30: Central | N30: FUR-CH-10001146 | O30: Furniture | P30: Chairs | Q30: Global Value Mid-Back Manager's Chair, Gray | R30: 213.115 | S30: 5 | T30: 0.3 | U30: -15.2225 | V30: 15.2225 | W30: 149.1805 | X30: {=IF(OR(R30:R567<0,T29:T567<0,C30:C568=""),"Check","OK")} -> Check | AB30: Total revenue | AC30: Avg order value | AD30: Total discount | AE30: count furniture | AF30: count consumer | AG30: furnitue &consumer | AH30: discount customer | AI30: Total qt sold | AJ30: Top product sales | AK30: Top category
A31: 68 | B31: CA-2014-106376 | C31: 41978 | D31: 41983 | E31: Standard Class | F31: BS-11590 | G31: Brendan Sweed | H31: Corporate | I31: United States | J31: Gilbert | K31: Arizona | L31: 85234 | M31: West | N31: OFF-AR-10002671 | O31: Office Supplies | P31: Art | Q31: Hunt BOSTON Model 1606 High-Volume Electric Pencil Sharpener, Beige | R31: 1113.024 | S31: 8 | T31: 0.2 | U31: 111.3024 | V31: 111.3024 | W31: 890.4192 | X31: {=IF(OR(R31:R568<0,T30:T568<0,C31:C569=""),"Check","OK")} -> Check | AB31: =SUM('Superstores sales dataset'!W2:W540) -> 94894.017 | AC31: =AVERAGE('Superstores sales dataset'!W2:W540) -> 176.38293 | AD31: =SUM(T2:T539) -> 85.32 | AE31: =COUNTIF('Superstores sales dataset'!O2:O540,"Furniture") -> 125 | AF31: =COUNTIF('Superstores sales dataset'!H2:H540,"Consumer") -> 289 | AG31: =COUNTIFS('Superstores sales dataset'!O2:O540,"Furniture",'Superstores sales dataset'!H2:H540,"Consumer") -> 64 | AH31: =AVERAGEIF('Superstores sales dataset'!H2:H540,"Consumer",'Superstores sales dataset'!T2:T539) -> 0.16006944 | AI31: =SUM('Superstores sales dataset'!S2:S539) -> -669065.64 | AJ31: =MAX(_xlfn.ANCHORARRAY('Superstores sales dataset'!W2)) -> 3999.99 | AK31: =SUMIF('Superstores sales dataset'!O2:O540,"Furniture",_xlfn.ANCHORARRAY('Superstores sales dataset'!W2)) -> 33662.173
A32: 70 | B32: CA-2016-119823 | C32: 42525 | D32: 42527 | E32: First Class | F32: KD-16270 | G32: Karen Daniels | H32: Consumer | I32: United States | J32: Springfield | K32: Virginia | L32: 22153 | M32: South | N32: OFF-PA-10000482 | O32: Office Supplies | P32: Paper | Q32: Snap-A-Way Black Print Carbonless Ruled Speed Letter, Triplicate | R32: 75.88 | S32: 2 | T32: 0 | U32: 35.6636 | V32: 35.6636 | W32: 75.88 | X32: {=IF(OR(R32:R569<0,T31:T569<0,C32:C570=""),"Check","OK")} -> Check
A33: 71 | B33: CA-2016-106075 | C33: 42631 | D33: 42636 | E33: Standard Class | F33: HM-14980 | G33: Henry MacAllister | H33: Consumer | I33: United States | J33: New York City | K33: New York | L33: 10009 | M33: East | N33: OFF-BI-10004654 | O33: Office Supplies | P33: Binders | Q33: Avery Binding System Hidden Tab Executive Style Index Sets | R33: 4.616 | S33: 1 | T33: 0.2 | U33: 1.731 | V33: 1.731 | W33: 3.6928 | X33: {=IF(OR(R33:R570<0,T32:T570<0,C33:C571=""),"Check","OK")} -> Check
A34: 72 | B34: CA-2017-114440 | C34: 42992 | D34: 42995 | E34: Second Class | F34: TB-21520 | G34: Tracy Blumstein | H34: Consumer | I34: United States | J34: Jackson | K34: Michigan | L34: 49201 | M34: Central | N34: OFF-PA-10004675 | O34: Office Supplies | P34: Paper | Q34: Telephone Message Books with Fax/Mobile Section, 5 1/2" x 3 3/16" | R34: 19.05 | S34: 3 | T34: 0 | U34: 8.763 | V34: 8.763 | W34: 19.05 | X34: {=IF(OR(R34:R571<0,T33:T571<0,C34:C572=""),"Check","OK")} -> Check
A35: 73 | B35: US-2015-134026 | C35: 42120 | D35: 42126 | E35: Standard Class | F35: JE-15745 | G35: Joel Eaton | H35: Consumer | I35: United States | J35: Memphis | K35: Tennessee | L35: 38109 | M35: South | N35: FUR-CH-10000513 | O35: Furniture | P35: Chairs | Q35: High-Back Leather Manager's Chair | R35: 831.936 | S35: 8 | T35: 0.2 | U35: -114.3912 | V35: 114.3912 | W35: 665.5488 | X35: {=IF(OR(R35:R572<0,T34:T572<0,C35:C573=""),"Check","OK")} -> Check
A36: 76 | B36: US-2017-118038 | C36: 43078 | D36: 43080 | E36: First Class | F36: KB-16600 | G36: Ken Brennan | H36: Corporate | I36: United States | J36: Houston | K36: Texas | L36: 77041 | M36: Central | N36: OFF-BI-10004182 | O36: Office Supplies | P36: Binders | Q36: Economy Binders | R36: 1.248 | S36: 3 | T36: 0.8 | U36: -1.9344 | V36: 1.9344 | W36: 0.2496 | X36: {=IF(OR(R36:R573<0,T35:T573<0,C36:C574=""),"Check","OK")} -> Check
A37: 79 | B37: US-2014-147606 | C37: 41969 | D37: 41974 | E37: Second Class | F37: JE-15745 | G37: Joel Eaton | H37: Consumer | I37: United States | J37: Houston | K37: Texas | L37: 77070 | M37: Central | N37: FUR-FU-10003194 | O37: Furniture | P37: Furnishings | Q37: Eldon Expressions Desk Accessory, Wood Pencil Holder, Oak | R37: 19.3 | S37: 5 | T37: 0.6 | U37: -14.475 | V37: 14.475 | W37: 7.72 | X37: {=IF(OR(R37:R574<0,T36:T574<0,C37:C575=""),"Check","OK")} -> Check
A38: 80 | B38: CA-2016-127208 | C38: 42533 | D38: 42536 | E38: First Class | F38: SC-20770 | G38: Stewart Carmichael | H38: Corporate | I38: United States | J38: Decatur | K38: Alabama | L38: 35601 | M38: South | N38: OFF-AP-10002118 | O38: Office Supplies | P38: Appliances | Q38: 1.7 Cubic Foot Compact "Cube" Office Refrigerators | R38: 208.16 | S38: 1 | T38: 0 | U38: 56.2032 | V38: 56.2032 | W38: 208.16 | X38: {=IF(OR(R38:R575<0,T37:T575<0,C38:C576=""),"Check","OK")} -> Check
A39: 82 | B39: CA-2014-139451 | C39: 41924 | D39: 41928 | E39: Standard Class | F39: DN-13690 | G39: Duane Noonan | H39: Consumer | I39: United States | J39: San Francisco | K39: California | L39: 94122 | M39: West | N39: OFF-AR-10002053 | O39: Office Supplies | P39: Art | Q39: Premium Writing Pencils, Soft, #2 by Central Association for the Blind | R39: 14.9 | S39: 5 | T39: 0 | U39: 4.172 | V39: 4.172 | W39: 14.9 | X39: {=IF(OR(R39:R576<0,T38:T576<0,C39:C577=""),"Check","OK")} -> Check
A40: 84 | B40: CA-2015-149734 | C40: 42250 | D40: 42255 | E40: Standard Class | F40: JC-16105 | G40: Julie Creighton | H40: Corporate | I40: United States | J40: Durham | K40: North Carolina | L40: 27707 | M40: South | N40: OFF-EN-10000927 | O40: Office Supplies | P40: Envelopes | Q40: Jet-Pak Recycled Peel 'N' Seal Padded Mailers | R40: 200.984 | S40: 7 | T40: 0.2 | U40: 62.8075 | V40: 62.8075 | W40: 160.7872 | X40: {=IF(OR(R40:R577<0,T39:T577<0,C40:C578=""),"Check","OK")} -> Check
A41: 85 | B41: US-2017-119662 | C41: 43052 | D41: 43055 | E41: First Class | F41: CS-12400 | G41: Christopher Schild | H41: Home Office | I41: United States | J41: Chicago | K41: Illinois | L41: 60623 | M41: Central | N41: OFF-ST-10003656 | O41: Office Supplies | P41: Storage | Q41: Safco Industrial Wire Shelving | R41: 230.376 | S41: 3 | T41: 0.2 | U41: -48.9549 | V41: 48.9549 | W41: 184.3008 | X41: {=IF(OR(R41:R578<0,T40:T578<0,C41:C579=""),"Check","OK")} -> Check
A42: 86 | B42: CA-2017-140088 | C42: 42883 | D42: 42885 | E42: Second Class | F42: PO-18865 | G42: Patrick O'Donnell | H42: Consumer | I42: United States | J42: Columbia | K42: South Carolina | L42: 29203 | M42: South | N42: FUR-CH-10000863 | O42: Furniture | P42: Chairs | Q42: Novimex Swivel Fabric Task Chair | R42: 301.96 | S42: 2 | T42: 0 | U42: 33.2156 | V42: 33.2156 | W42: 301.96 | X42: {=IF(OR(R42:R579<0,T41:T579<0,C42:C580=""),"Check","OK")} -> Check
A43: 87 | B43: CA-2017-155558 | C43: 43034 | D43: 43041 | E43: Standard Class | F43: PG-18895 | G43: Paul Gonzalez | H43: Consumer | I43: United States | J43: Rochester | K43: Minnesota | L43: 55901 | M43: Central | N43: TEC-AC-10001998 | O43: Technology | P43: Accessories | Q43: LogitechLS21 Speaker System - PC Multimedia - 2.1-CH - Wired | R43: 19.99 | S43: 1 | T43: 0 | U43: 6.7966 | V43: 6.7966 | W43: 19.99 | X43: {=IF(OR(R43:R580<0,T42:T580<0,C43:C581=""),"Check","OK")} -> Check
... A531: 9146 | B531: CA-2015-126970 | C531: 42267 | D531: 42271 | E531: Standard Class | F531: TP-21130 | G531: Theone Pippenger | H531: Consumer | I531: United States | J531: Naperville | K531: Illinois | L531: 60540 | M531: Central | N531: OFF-BI-10000138 | O531: Office Supplies | P531: Binders | Q531: Acco Translucent Poly Ring Binders | R531: 2.808 | S531: 3 | T531: 0.8 | U531: -4.4928 | V531: 4.4928 | W531: 0.5616 | X531: {=IF(OR(R531:R1068<0,T530:T1068<0,C531:C1069=""),"Check","OK")} -> Check
A532: 9147 | B532: US-2016-165505 | C532: 42392 | D532: 42396 | E532: Standard Class | F532: CB-12535 | G532: Claudia Bergmann | H532: Corporate | I532: United States | J532: Burlington | K532: Vermont | L532: 05408 | M532: East | N532: TEC-AC-10002926 | O532: Technology | P532: Accessories | Q532: Logitech Wireless Marathon Mouse M705 | R532: 99.98 | S532: 2 | T532: 0 | U532: 42.9914 | V532: 42.9914 | W532: 99.98 | X532: {=IF(OR(R532:R1069<0,T531:T1069<0,C532:C1070=""),"Check","OK")} -> Check
A533: 9150 | B533: US-2014-157070 | C533: 41791 | D533: 41796 | E533: Standard Class | F533: QJ-19255 | G533: Quincy Jones | H533: Corporate | I533: United States | J533: Detroit | K533: Michigan | L533: 48234 | M533: Central | N533: OFF-BI-10001765 | O533: Office Supplies | P533: Binders | Q533: Wilson Jones Heavy-Duty Casebound Ring Binders with Metal Hinges | R533: 138.56 | S533: 4 | T533: 0 | U533: 66.5088 | V533: 66.5088 | W533: 138.56 | X533: {=IF(OR(R533:R1070<0,T532:T1070<0,C533:C1071=""),"Check","OK")} -> Check
A534: 9152 | B534: US-2015-106873 | C534: 42271 | D534: 42276 | E534: Second Class | F534: KM-16720 | G534: Kunst Miller | H534: Consumer | I534: United States | J534: Avondale | K534: Arizona | L534: 85323 | M534: West | N534: OFF-AR-10003179 | O534: Office Supplies | P534: Art | Q534: Dixon Ticonderoga Core-Lock Colored Pencils | R534: 14.576 | S534: 2 | T534: 0.2 | U534: 2.3686 | V534: 2.3686 | W534: 11.6608 | X534: {=IF(OR(R534:R1071<0,T533:T1071<0,C534:C1072=""),"Check","OK")} -> Check
A535: 9155 | B535: CA-2016-132990 | C535: 42583 | D535: 42585 | E535: Second Class | F535: KM-16660 | G535: Khloe Miller | H535: Consumer | I535: United States | J535: Philadelphia | K535: Pennsylvania | L535: 19140 | M535: East | N535: FUR-FU-10004864 | O535: Furniture | P535: Furnishings | Q535: Eldon 500 Class Desk Accessories | R535: 19.312 | S535: 2 | T535: 0.2 | U535: 3.1382 | V535: 3.1382 | W535: 15.4496 | X535: {=IF(OR(R535:R1072<0,T534:T1072<0,C535:C1073=""),"Check","OK")} -> Check
A536: 9156 | B536: CA-2014-102645 | C536: 41662 | D536: 41667 | E536: Standard Class | F536: IM-15055 | G536: Ionia McGrath | H536: Consumer | I536: United States | J536: Las Vegas | K536: Nevada | L536: 89115 | M536: West | N536: OFF-PA-10001804 | O536: Office Supplies | P536: Paper | Q536: Xerox 195 | R536: 40.08 | S536: 6 | T536: 0 | U536: 19.2384 | V536: 19.2384 | W536: 40.08 | X536: {=IF(OR(R536:R1073<0,T535:T1073<0,C536:C1074=""),"Check","OK")} -> Check
A537: 9157 | B537: CA-2014-134215 | C537: 41855 | D537: 41859 | E537: Standard Class | F537: ML-17395 | G537: Marina Lichtenstein | H537: Corporate | I537: United States | J537: Bangor | K537: Maine | L537: 4401 | M537: East | N537: OFF-AP-10001271 | O537: Office Supplies | P537: Appliances | Q537: Eureka The Boss Cordless Rechargeable Stick Vac | R537: 101.96 | S537: 2 | T537: 0 | U537: 27.5292 | V537: 27.5292 | W537: 101.96 | X537: {=IF(OR(R537:R1074<0,T536:T1074<0,C537:C1075=""),"Check","OK")} -> Check
...

Sheet Dashboard
